{
  "name": "DoNotThrowExceptionInFinally",
  "language": "java",
  "description": "\nThrowing exceptions within a 'finally' block is confusing since they may mask other exceptions\nor code defects.\nNote: This is a PMD implementation of the Lint4j rule \"A throw in a finally block\"\n        ",
  "example": "public class Foo {\n    public void bar() {\n        try {\n            // Here do some stuff\n        } catch( Exception e) {\n            // Handling the issue\n        } finally {\n            // is this really a good idea ?\n            throw new Exception();\n        }\n    }\n}",
  "cwe": null,
  "cwe-description": null,
  "checker-language": "java",
  "loc": 0,
  "branches": 0,
  "apis": 0,
  "test": [
    {
      "description": "classic failure case",
      "expected-problems": 1,
      "expected-linenumbers": [
        8
      ],
      "code": "\npublic class Foo {\n    public void bar() {\n        try {\n            // Here do some stuff\n        }\n        catch( Exception e) {\n            // Handling the issue\n        } finally {\n            // is this really a good idea ?\n            throw new Exception();\n        }\n    }\n}\n        "
    }
  ]
}